Workbook

Sheet Закуп
A1: Закуп без НДС | B1: Закуп с НДС | C1: № | D1: Поставщ Произв 0-нет | E1: ✔️ Коробки | F1: Коммент | G1: Тип | H1: Fefco | I1: Профиль В Е | J1: Форма чья? | K1: SKU eng | L1: sale | M1: Ц или М | N1: Каталог | O1: V л знач | P1: V л сайт | Q1: V л прайс | R1: Д | S1: Ш | T1: В | U1: S загот м2 F/Знач (2×(Д+Ш)+60) × (Ш+В+8) | V1: Длинные | W1: Плоские | X1: Наибольшые сторона, мм &emsp; | Y1: Средняя сторона, мм &emsp; | Z1: Наименьшые сторона, мм &emsp; | AA1: Тип коробки &emsp; | AB1: Цена м2 руб без НДС | AC1: Объем, литров для сайта старые
A2: 0.28 | B2: =A2*1.2 -> 0.336 | C2: 2 | D2: У | E2: 230х85х150 | G2: Ч | H2: 0201 | I2: В | J2: х | K2: K1 | N2: =IF(D2="","",IF(LEFT(D2,1)="0",0,1)) -> 1 | O2: =ROUND(R2*S2*T2/1000000,2) -> 2.93 | P2: =IF(O2="","", IF(O2<1,"0,1-0,9 литров", IF(O2<2,"1-1,9 литра", IF(O2<3,"2-2,9 литра", IF(O2<4,"3-3,9 литра", IF(O2<6,"4-5,9 литра",IF(O2<8,"6-7,9 литра",IF(O2<10,"8-9,9 литров",IF(O2<15,"10-14,9 литров",IF(O2<20,"15-19,9 литров",IF(O2<30,"20-29 литров",IF(O2<50,"30-49 литров",IF(O2<60,"50-59 литров",IF(O2<70,"60-69 литров",IF(O2<80,"70-79 литров",IF(O2<90,"80-89 литров",IF(O2<100,"90-99 литров",IF(O2<200,"100-200 литров","200+ литров")))))))))))))))))) -> 2-2,9 литра | Q2: =IF(O2="","",IF(O2<1,"<1 л",IF(O2<=2,"1-2 л",IF(O2<=3,"2-3 л",IF(O2<=5,"3-5 л",IF(O2<=10,"5-10 л",IF(O2<=20,"10-20 л",IF(O2<=50,"20-50 л",IF(O2<=100,"50-100 л","100+ л"))))))))) -> 2-3 л | R2: =IF(E2="","",--LEFT(E2,FIND("х",E2)-1)) -> 230 | S2: =IF(E2="","",--MID(E2,FIND("х",E2)+1,FIND("х",E2,FIND("х",E2)+1)-FIND("х",E2)-1)) -> 85 | T2: =IF(E2="","",--RIGHT(E2,LEN(E2)-FIND("х",E2,FIND("х",E2)+1))) -> 150 | U2: =(2*(R2+S2)+60)*(S2+T2+8)/1000000 -> 0.16767 | V2: =IF(OR(AND(R2>=2*S2,R2>=2*T2),AND(S2>=2*R2,S2>=2*T2),AND(T2>=2*R2,T2>=2*S2)),"Длинные","") | W2: =IF(OR(AND(R2<=S2/2,R2<=T2/2),AND(S2<=R2/2,S2<=T2/2),AND(T2<=R2/2,T2<=S2/2)),"Плоские","") | X2: =IF(LARGE($R2:$T2,1)="","",IF(LARGE($R2:$T2,1)<=99,"10-99 мм",IF(LARGE($R2:$T2,1)<=199,"100-199 мм",IF(LARGE($R2:$T2,1)<=299,"200-299 мм",IF(LARGE($R2:$T2,1)<=399,"300-399 мм",IF(LARGE($R2:$T2,1)<=499,"400-499 мм",IF(LARGE($R2:$T2,1)<=599,"500-599 мм",IF(LARGE($R2:$T2,1)<=699,"600-699 мм",IF(LARGE($R2:$T2,1)<=999,"700-999 мм","1000+ мм"))))))))) -> 200-299 мм | Y2: =IF(LARGE($R2:$T2,2)="","",IF(LARGE($R2:$T2,2)<=99,"10-99 мм",IF(LARGE($R2:$T2,2)<=199,"100-199 мм",IF(LARGE($R2:$T2,2)<=299,"200-299 мм",IF(LARGE($R2:$T2,2)<=399,"300-399 мм",IF(LARGE($R2:$T2,2)<=499,"400-499 мм",IF(LARGE($R2:$T2,2)<=599,"500-599 мм",IF(LARGE($R2:$T2,2)<=699,"600-699 мм",IF(LARGE($R2:$T2,2)<=999,"700-999 мм","1000+ мм"))))))))) -> 100-199 мм | Z2: =IF(SMALL($R2:$T2,1)="","",IF(SMALL($R2:$T2,1)<=99,"10-99 мм",IF(SMALL($R2:$T2,1)<=199,"100-199 мм",IF(SMALL($R2:$T2,1)<=299,"200-299 мм",IF(SMALL($R2:$T2,1)<=399,"300-399 мм",IF(SMALL($R2:$T2,1)<=499,"400-499 мм",IF(SMALL($R2:$T2,1)<=599,"500-599 мм",IF(SMALL($R2:$T2,1)<=699,"600-699 мм",IF(SMALL($R2:$T2,1)<=999,"700-999 мм","1000+ мм"))))))))) -> 10-99 мм | AA2: =IF(G2="","",IF(G2="Л","Лист гофрокартона",IF(G2="КД","Крышка-дно",IF(G2="С","Самосборные",IF(G2="Ч","Четырехклапанные",IF(G2="А","Архивные","Неизвестно")))))) -> Четырехклапанные | AB2: 1.73 | AC2: =IF(O2="","",IF(O2<=1,"0-1 литров",IF(O2<=3,"2-3 литра",IF(O2<=5,"4-5 литра",IF(O2<=7,"6-7 литра",IF(O2<=9,"8-9 литров",IF(O2<=14,"10-14 литров",IF(O2<=19,"15-19 литров",IF(O2<=29,"20-29 литров",IF(O2<=49,"30-49 литров",IF(O2<=59,"50-59 литров",IF(O2<=70,"60-69 литров",IF(O2<=79,"70-79 литров",IF(O2<=89,"80-89 литров",IF(O2<=99,"90-99 литров",IF(O2<=200,"100-200 литров","200+ литров")))))))))))))))) -> 2-3 литра
A3: 0.73 | B3: =A3*1.2 -> 0.876 | C3: 3 | D3: У | E3: 245х245х165 | G3: Ч | H3: 0201 | I3: В | J3: х | K3: K2 | N3: =IF(D3="","",IF(LEFT(D3,1)="0",0,1)) -> 1 | O3: =ROUND(R3*S3*T3/1000000,2) -> 9.9 | P3: =IF(O3="","", IF(O3<1,"0,1-0,9 литров", IF(O3<2,"1-1,9 литра", IF(O3<3,"2-2,9 литра", IF(O3<4,"3-3,9 литра", IF(O3<6,"4-5,9 литра",IF(O3<8,"6-7,9 литра",IF(O3<10,"8-9,9 литров",IF(O3<15,"10-14,9 литров",IF(O3<20,"15-19,9 литров",IF(O3<30,"20-29 литров",IF(O3<50,"30-49 литров",IF(O3<60,"50-59 литров",IF(O3<70,"60-69 литров",IF(O3<80,"70-79 литров",IF(O3<90,"80-89 литров",IF(O3<100,"90-99 литров",IF(O3<200,"100-200 литров","200+ литров")))))))))))))))))) -> 8-9,9 литров | Q3: =IF(O3="","",IF(O3<1,"<1 л",IF(O3<=2,"1-2 л",IF(O3<=3,"2-3 л",IF(O3<=5,"3-5 л",IF(O3<=10,"5-10 л",IF(O3<=20,"10-20 л",IF(O3<=50,"20-50 л",IF(O3<=100,"50-100 л","100+ л"))))))))) -> 5-10 л | R3: =IF(E3="","",--LEFT(E3,FIND("х",E3)-1)) -> 245 | S3: =IF(E3="","",--MID(E3,FIND("х",E3)+1,FIND("х",E3,FIND("х",E3)+1)-FIND("х",E3)-1)) -> 245 | T3: =IF(E3="","",--RIGHT(E3,LEN(E3)-FIND("х",E3,FIND("х",E3)+1))) -> 165 | U3: =(2*(R3+S3)+60)*(S3+T3+8)/1000000 -> 0.43472 | V3: =IF(OR(AND(R3>=2*S3,R3>=2*T3),AND(S3>=2*R3,S3>=2*T3),AND(T3>=2*R3,T3>=2*S3)),"Длинные","") | W3: =IF(OR(AND(R3<=S3/2,R3<=T3/2),AND(S3<=R3/2,S3<=T3/2),AND(T3<=R3/2,T3<=S3/2)),"Плоские","") | X3: =IF(LARGE($R3:$T3,1)="","",IF(LARGE($R3:$T3,1)<=99,"10-99 мм",IF(LARGE($R3:$T3,1)<=199,"100-199 мм",IF(LARGE($R3:$T3,1)<=299,"200-299 мм",IF(LARGE($R3:$T3,1)<=399,"300-399 мм",IF(LARGE($R3:$T3,1)<=499,"400-499 мм",IF(LARGE($R3:$T3,1)<=599,"500-599 мм",IF(LARGE($R3:$T3,1)<=699,"600-699 мм",IF(LARGE($R3:$T3,1)<=999,"700-999 мм","1000+ мм"))))))))) -> 200-299 мм | Y3: =IF(LARGE($R3:$T3,2)="","",IF(LARGE($R3:$T3,2)<=99,"10-99 мм",IF(LARGE($R3:$T3,2)<=199,"100-199 мм",IF(LARGE($R3:$T3,2)<=299,"200-299 мм",IF(LARGE($R3:$T3,2)<=399,"300-399 мм",IF(LARGE($R3:$T3,2)<=499,"400-499 мм",IF(LARGE($R3:$T3,2)<=599,"500-599 мм",IF(LARGE($R3:$T3,2)<=699,"600-699 мм",IF(LARGE($R3:$T3,2)<=999,"700-999 мм","1000+ мм"))))))))) -> 200-299 мм | Z3: =IF(SMALL($R3:$T3,1)="","",IF(SMALL($R3:$T3,1)<=99,"10-99 мм",IF(SMALL($R3:$T3,1)<=199,"100-199 мм",IF(SMALL($R3:$T3,1)<=299,"200-299 мм",IF(SMALL($R3:$T3,1)<=399,"300-399 мм",IF(SMALL($R3:$T3,1)<=499,"400-499 мм",IF(SMALL($R3:$T3,1)<=599,"500-599 мм",IF(SMALL($R3:$T3,1)<=699,"600-699 мм",IF(SMALL($R3:$T3,1)<=999,"700-999 мм","1000+ мм"))))))))) -> 100-199 мм | AA3: =IF(G3="","",IF(G3="Л","Лист гофрокартона",IF(G3="КД","Крышка-дно",IF(G3="С","Самосборные",IF(G3="Ч","Четырехклапанные",IF(G3="А","Архивные","Неизвестно")))))) -> Четырехклапанные | AB3: 1.73 | AC3: =IF(O3="","",IF(O3<=1,"0-1 литров",IF(O3<=3,"2-3 литра",IF(O3<=5,"4-5 литра",IF(O3<=7,"6-7 литра",IF(O3<=9,"8-9 литров",IF(O3<=14,"10-14 литров",IF(O3<=19,"15-19 литров",IF(O3<=29,"20-29 литров",IF(O3<=49,"30-49 литров",IF(O3<=59,"50-59 литров",IF(O3<=70,"60-69 литров",IF(O3<=79,"70-79 литров",IF(O3<=89,"80-89 литров",IF(O3<=99,"90-99 литров",IF(O3<=200,"100-200 литров","200+ литров")))))))))))))))) -> 10-14 литров
A4: 0.51 | B4: =A4*1.2 -> 0.612 | C4: 4 | D4: У | E4: 380х160х100 | G4: Ч | H4: 0201 | I4: В | J4: х | K4: K3 | N4: =IF(D4="","",IF(LEFT(D4,1)="0",0,1)) -> 1 | O4: =ROUND(R4*S4*T4/1000000,2) -> 6.08 | P4: =IF(O4="","", IF(O4<1,"0,1-0,9 литров", IF(O4<2,"1-1,9 литра", IF(O4<3,"2-2,9 литра", IF(O4<4,"3-3,9 литра", IF(O4<6,"4-5,9 литра",IF(O4<8,"6-7,9 литра",IF(O4<10,"8-9,9 литров",IF(O4<15,"10-14,9 литров",IF(O4<20,"15-19,9 литров",IF(O4<30,"20-29 литров",IF(O4<50,"30-49 литров",IF(O4<60,"50-59 литров",IF(O4<70,"60-69 литров",IF(O4<80,"70-79 литров",IF(O4<90,"80-89 литров",IF(O4<100,"90-99 литров",IF(O4<200,"100-200 литров","200+ литров")))))))))))))))))) -> 6-7,9 литра | Q4: =IF(O4="","",IF(O4<1,"<1 л",IF(O4<=2,"1-2 л",IF(O4<=3,"2-3 л",IF(O4<=5,"3-5 л",IF(O4<=10,"5-10 л",IF(O4<=20,"10-20 л",IF(O4<=50,"20-50 л",IF(O4<=100,"50-100 л","100+ л"))))))))) -> 5-10 л | R4: =IF(E4="","",--LEFT(E4,FIND("х",E4)-1)) -> 380 | S4: =IF(E4="","",--MID(E4,FIND("х",E4)+1,FIND("х",E4,FIND("х",E4)+1)-FIND("х",E4)-1)) -> 160 | T4: =IF(E4="","",--RIGHT(E4,LEN(E4)-FIND("х",E4,FIND("х",E4)+1))) -> 100 | U4: =(2*(R4+S4)+60)*(S4+T4+8)/1000000 -> 0.30552 | V4: =IF(OR(AND(R4>=2*S4,R4>=2*T4),AND(S4>=2*R4,S4>=2*T4),AND(T4>=2*R4,T4>=2*S4)),"Длинные","") -> Длинные | W4: =IF(OR(AND(R4<=S4/2,R4<=T4/2),AND(S4<=R4/2,S4<=T4/2),AND(T4<=R4/2,T4<=S4/2)),"Плоские","") | X4: =IF(LARGE($R4:$T4,1)="","",IF(LARGE($R4:$T4,1)<=99,"10-99 мм",IF(LARGE($R4:$T4,1)<=199,"100-199 мм",IF(LARGE($R4:$T4,1)<=299,"200-299 мм",IF(LARGE($R4:$T4,1)<=399,"300-399 мм",IF(LARGE($R4:$T4,1)<=499,"400-499 мм",IF(LARGE($R4:$T4,1)<=599,"500-599 мм",IF(LARGE($R4:$T4,1)<=699,"600-699 мм",IF(LARGE($R4:$T4,1)<=999,"700-999 мм","1000+ мм"))))))))) -> 300-399 мм | Y4: =IF(LARGE($R4:$T4,2)="","",IF(LARGE($R4:$T4,2)<=99,"10-99 мм",IF(LARGE($R4:$T4,2)<=199,"100-199 мм",IF(LARGE($R4:$T4,2)<=299,"200-299 мм",IF(LARGE($R4:$T4,2)<=399,"300-399 мм",IF(LARGE($R4:$T4,2)<=499,"400-499 мм",IF(LARGE($R4:$T4,2)<=599,"500-599 мм",IF(LARGE($R4:$T4,2)<=699,"600-699 мм",IF(LARGE($R4:$T4,2)<=999,"700-999 мм","1000+ мм"))))))))) -> 100-199 мм | Z4: =IF(SMALL($R4:$T4,1)="","",IF(SMALL($R4:$T4,1)<=99,"10-99 мм",IF(SMALL($R4:$T4,1)<=199,"100-199 мм",IF(SMALL($R4:$T4,1)<=299,"200-299 мм",IF(SMALL($R4:$T4,1)<=399,"300-399 мм",IF(SMALL($R4:$T4,1)<=499,"400-499 мм",IF(SMALL($R4:$T4,1)<=599,"500-599 мм",IF(SMALL($R4:$T4,1)<=699,"600-699 мм",IF(SMALL($R4:$T4,1)<=999,"700-999 мм","1000+ мм"))))))))) -> 100-199 мм | AA4: =IF(G4="","",IF(G4="Л","Лист гофрокартона",IF(G4="КД","Крышка-дно",IF(G4="С","Самосборные",IF(G4="Ч","Четырехклапанные",IF(G4="А","Архивные","Неизвестно")))))) -> Четырехклапанные | AB4: 1.73 | AC4: =IF(O4="","",IF(O4<=1,"0-1 литров",IF(O4<=3,"2-3 литра",IF(O4<=5,"4-5 литра",IF(O4<=7,"6-7 литра",IF(O4<=9,"8-9 литров",IF(O4<=14,"10-14 литров",IF(O4<=19,"15-19 литров",IF(O4<=29,"20-29 литров",IF(O4<=49,"30-49 литров",IF(O4<=59,"50-59 литров",IF(O4<=70,"60-69 литров",IF(O4<=79,"70-79 литров",IF(O4<=89,"80-89 литров",IF(O4<=99,"90-99 литров",IF(O4<=200,"100-200 литров","200+ литров")))))))))))))))) -> 6-7 литра
A5: 2.48 | B5: =A5*1.2 -> 2.976 | C5: 5 | D5: У | E5: 460х410х390 | G5: Ч | H5: 0201 | I5: В | J5: х | K5: K4 | N5: =IF(D5="","",IF(LEFT(D5,1)="0",0,1)) -> 1 | O5: =ROUND(R5*S5*T5/1000000,2) -> 73.55 | P5: =IF(O5="","", IF(O5<1,"0,1-0,9 литров", IF(O5<2,"1-1,9 литра", IF(O5<3,"2-2,9 литра", IF(O5<4,"3-3,9 литра", IF(O5<6,"4-5,9 литра",IF(O5<8,"6-7,9 литра",IF(O5<10,"8-9,9 литров",IF(O5<15,"10-14,9 литров",IF(O5<20,"15-19,9 литров",IF(O5<30,"20-29 литров",IF(O5<50,"30-49 литров",IF(O5<60,"50-59 литров",IF(O5<70,"60-69 литров",IF(O5<80,"70-79 литров",IF(O5<90,"80-89 литров",IF(O5<100,"90-99 литров",IF(O5<200,"100-200 литров","200+ литров")))))))))))))))))) -> 70-79 литров | Q5: =IF(O5="","",IF(O5<1,"<1 л",IF(O5<=2,"1-2 л",IF(O5<=3,"2-3 л",IF(O5<=5,"3-5 л",IF(O5<=10,"5-10 л",IF(O5<=20,"10-20 л",IF(O5<=50,"20-50 л",IF(O5<=100,"50-100 л","100+ л"))))))))) -> 50-100 л | R5: =IF(E5="","",--LEFT(E5,FIND("х",E5)-1)) -> 460 | S5: =IF(E5="","",--MID(E5,FIND("х",E5)+1,FIND("х",E5,FIND("х",E5)+1)-FIND("х",E5)-1)) -> 410 | T5: =IF(E5="","",--RIGHT(E5,LEN(E5)-FIND("х",E5,FIND("х",E5)+1))) -> 390 | U5: =(2*(R5+S5)+60)*(S5+T5+8)/1000000 -> 1.4544 | V5: =IF(OR(AND(R5>=2*S5,R5>=2*T5),AND(S5>=2*R5,S5>=2*T5),AND(T5>=2*R5,T5>=2*S5)),"Длинные","") | W5: =IF(OR(AND(R5<=S5/2,R5<=T5/2),AND(S5<=R5/2,S5<=T5/2),AND(T5<=R5/2,T5<=S5/2)),"Плоские","") | X5: =IF(LARGE($R5:$T5,1)="","",IF(LARGE($R5:$T5,1)<=99,"10-99 мм",IF(LARGE($R5:$T5,1)<=199,"100-199 мм",IF(LARGE($R5:$T5,1)<=299,"200-299 мм",IF(LARGE($R5:$T5,1)<=399,"300-399 мм",IF(LARGE($R5:$T5,1)<=499,"400-499 мм",IF(LARGE($R5:$T5,1)<=599,"500-599 мм",IF(LARGE($R5:$T5,1)<=699,"600-699 мм",IF(LARGE($R5:$T5,1)<=999,"700-999 мм","1000+ мм"))))))))) -> 400-499 мм | Y5: =IF(LARGE($R5:$T5,2)="","",IF(LARGE($R5:$T5,2)<=99,"10-99 мм",IF(LARGE($R5:$T5,2)<=199,"100-199 мм",IF(LARGE($R5:$T5,2)<=299,"200-299 мм",IF(LARGE($R5:$T5,2)<=399,"300-399 мм",IF(LARGE($R5:$T5,2)<=499,"400-499 мм",IF(LARGE($R5:$T5,2)<=599,"500-599 мм",IF(LARGE($R5:$T5,2)<=699,"600-699 мм",IF(LARGE($R5:$T5,2)<=999,"700-999 мм","1000+ мм"))))))))) -> 400-499 мм | Z5: =IF(SMALL($R5:$T5,1)="","",IF(SMALL($R5:$T5,1)<=99,"10-99 мм",IF(SMALL($R5:$T5,1)<=199,"100-199 мм",IF(SMALL($R5:$T5,1)<=299,"200-299 мм",IF(SMALL($R5:$T5,1)<=399,"300-399 мм",IF(SMALL($R5:$T5,1)<=499,"400-499 мм",IF(SMALL($R5:$T5,1)<=599,"500-599 мм",IF(SMALL($R5:$T5,1)<=699,"600-699 мм",IF(SMALL($R5:$T5,1)<=999,"700-999 мм","1000+ мм"))))))))) -> 300-399 мм | AA5: =IF(G5="","",IF(G5="Л","Лист гофрокартона",IF(G5="КД","Крышка-дно",IF(G5="С","Самосборные",IF(G5="Ч","Четырехклапанные",IF(G5="А","Архивные","Неизвестно")))))) -> Четырехклапанные | AB5: 1.73 | AC5: =IF(O5="","",IF(O5<=1,"0-1 литров",IF(O5<=3,"2-3 литра",IF(O5<=5,"4-5 литра",IF(O5<=7,"6-7 литра",IF(O5<=9,"8-9 литров",IF(O5<=14,"10-14 литров",IF(O5<=19,"15-19 литров",IF(O5<=29,"20-29 литров",IF(O5<=49,"30-49 литров",IF(O5<=59,"50-59 литров",IF(O5<=70,"60-69 литров",IF(O5<=79,"70-79 литров",IF(O5<=89,"80-89 литров",IF(O5<=99,"90-99 литров",IF(O5<=200,"100-200 литров","200+ литров")))))))))))))))) -> 70-79 литров
A6: 2.2 | B6: =A6*1.2 -> 2.64 | C6: 6 | D6: У | E6: 460х310х490 | G6: Ч | H6: 0201 | I6: В | J6: х | K6: K5 | N6: =IF(D6="","",IF(LEFT(D6,1)="0",0,1)) -> 1 | O6: =ROUND(R6*S6*T6/1000000,2) -> 69.87 | P6: =IF(O6="","", IF(O6<1,"0,1-0,9 литров", IF(O6<2,"1-1,9 литра", IF(O6<3,"2-2,9 литра", IF(O6<4,"3-3,9 литра", IF(O6<6,"4-5,9 литра",IF(O6<8,"6-7,9 литра",IF(O6<10,"8-9,9 литров",IF(O6<15,"10-14,9 литров",IF(O6<20,"15-19,9 литров",IF(O6<30,"20-29 литров",IF(O6<50,"30-49 литров",IF(O6<60,"50-59 литров",IF(O6<70,"60-69 литров",IF(O6<80,"70-79 литров",IF(O6<90,"80-89 литров",IF(O6<100,"90-99 литров",IF(O6<200,"100-200 литров","200+ литров")))))))))))))))))) -> 60-69 литров | Q6: =IF(O6="","",IF(O6<1,"<1 л",IF(O6<=2,"1-2 л",IF(O6<=3,"2-3 л",IF(O6<=5,"3-5 л",IF(O6<=10,"5-10 л",IF(O6<=20,"10-20 л",IF(O6<=50,"20-50 л",IF(O6<=100,"50-100 л","100+ л"))))))))) -> 50-100 л | R6: =IF(E6="","",--LEFT(E6,FIND("х",E6)-1)) -> 460 | S6: =IF(E6="","",--MID(E6,FIND("х",E6)+1,FIND("х",E6,FIND("х",E6)+1)-FIND("х",E6)-1)) -> 310 | T6: =IF(E6="","",--RIGHT(E6,LEN(E6)-FIND("х",E6,FIND("х",E6)+1))) -> 490 | U6: =(2*(R6+S6)+60)*(S6+T6+8)/1000000 -> 1.2928 | V6: =IF(OR(AND(R6>=2*S6,R6>=2*T6),AND(S6>=2*R6,S6>=2*T6),AND(T6>=2*R6,T6>=2*S6)),"Длинные","") | W6: =IF(OR(AND(R6<=S6/2,R6<=T6/2),AND(S6<=R6/2,S6<=T6/2),AND(T6<=R6/2,T6<=S6/2)),"Плоские","") | X6: =IF(LARGE($R6:$T6,1)="","",IF(LARGE($R6:$T6,1)<=99,"10-99 мм",IF(LARGE($R6:$T6,1)<=199,"100-199 мм",IF(LARGE($R6:$T6,1)<=299,"200-299 мм",IF(LARGE($R6:$T6,1)<=399,"300-399 мм",IF(LARGE($R6:$T6,1)<=499,"400-499 мм",IF(LARGE($R6:$T6,1)<=599,"500-599 мм",IF(LARGE($R6:$T6,1)<=699,"600-699 мм",IF(LARGE($R6:$T6,1)<=999,"700-999 мм","1000+ мм"))))))))) -> 400-499 мм | Y6: =IF(LARGE($R6:$T6,2)="","",IF(LARGE($R6:$T6,2)<=99,"10-99 мм",IF(LARGE($R6:$T6,2)<=199,"100-199 мм",IF(LARGE($R6:$T6,2)<=299,"200-299 мм",IF(LARGE($R6:$T6,2)<=399,"300-399 мм",IF(LARGE($R6:$T6,2)<=499,"400-499 мм",IF(LARGE($R6:$T6,2)<=599,"500-599 мм",IF(LARGE($R6:$T6,2)<=699,"600-699 мм",IF(LARGE($R6:$T6,2)<=999,"700-999 мм","1000+ мм"))))))))) -> 400-499 мм | Z6: =IF(SMALL($R6:$T6,1)="","",IF(SMALL($R6:$T6,1)<=99,"10-99 мм",IF(SMALL($R6:$T6,1)<=199,"100-199 мм",IF(SMALL($R6:$T6,1)<=299,"200-299 мм",IF(SMALL($R6:$T6,1)<=399,"300-399 мм",IF(SMALL($R6:$T6,1)<=499,"400-499 мм",IF(SMALL($R6:$T6,1)<=599,"500-599 мм",IF(SMALL($R6:$T6,1)<=699,"600-699 мм",IF(SMALL($R6:$T6,1)<=999,"700-999 мм","1000+ мм"))))))))) -> 300-399 мм | AA6: =IF(G6="","",IF(G6="Л","Лист гофрокартона",IF(G6="КД","Крышка-дно",IF(G6="С","Самосборные",IF(G6="Ч","Четырехклапанные",IF(G6="А","Архивные","Неизвестно")))))) -> Четырехклапанные | AB6: 1.73 | AC6: =IF(O6="","",IF(O6<=1,"0-1 литров",IF(O6<=3,"2-3 литра",IF(O6<=5,"4-5 литра",IF(O6<=7,"6-7 литра",IF(O6<=9,"8-9 литров",IF(O6<=14,"10-14 литров",IF(O6<=19,"15-19 литров",IF(O6<=29,"20-29 литров",IF(O6<=49,"30-49 литров",IF(O6<=59,"50-59 литров",IF(O6<=70,"60-69 литров",IF(O6<=79,"70-79 литров",IF(O6<=89,"80-89 литров",IF(O6<=99,"90-99 литров",IF(O6<=200,"100-200 литров","200+ литров")))))))))))))))) -> 60-69 литров
A7: 3.05 | B7: =A7*1.2 -> 3.66 | C7: 7 | D7: У | E7: 585х385х500 | G7: Ч | H7: 0201 | I7: В | J7: х | K7: K6 | N7: =IF(D7="","",IF(LEFT(D7,1)="0",0,1)) -> 1 | O7: =ROUND(R7*S7*T7/1000000,2) -> 112.61 | P7: =IF(O7="","", IF(O7<1,"0,1-0,9 литров", IF(O7<2,"1-1,9 литра", IF(O7<3,"2-2,9 литра", IF(O7<4,"3-3,9 литра", IF(O7<6,"4-5,9 литра",IF(O7<8,"6-7,9 литра",IF(O7<10,"8-9,9 литров",IF(O7<15,"10-14,9 литров",IF(O7<20,"15-19,9 литров",IF(O7<30,"20-29 литров",IF(O7<50,"30-49 литров",IF(O7<60,"50-59 литров",IF(O7<70,"60-69 литров",IF(O7<80,"70-79 литров",IF(O7<90,"80-89 литров",IF(O7<100,"90-99 литров",IF(O7<200,"100-200 литров","200+ литров")))))))))))))))))) -> 100-200 литров | Q7: =IF(O7="","",IF(O7<1,"<1 л",IF(O7<=2,"1-2 л",IF(O7<=3,"2-3 л",IF(O7<=5,"3-5 л",IF(O7<=10,"5-10 л",IF(O7<=20,"10-20 л",IF(O7<=50,"20-50 л",IF(O7<=100,"50-100 л","100+ л"))))))))) -> 100+ л | R7: =IF(E7="","",--LEFT(E7,FIND("х",E7)-1)) -> 585 | S7: =IF(E7="","",--MID(E7,FIND("х",E7)+1,FIND("х",E7,FIND("х",E7)+1)-FIND("х",E7)-1)) -> 385 | T7: =IF(E7="","",--RIGHT(E7,LEN(E7)-FIND("х",E7,FIND("х",E7)+1))) -> 500 | U7: =(2*(R7+S7)+60)*(S7+T7+8)/1000000 -> 1.786 | V7: =IF(OR(AND(R7>=2*S7,R7>=2*T7),AND(S7>=2*R7,S7>=2*T7),AND(T7>=2*R7,T7>=2*S7)),"Длинные","") | W7: =IF(OR(AND(R7<=S7/2,R7<=T7/2),AND(S7<=R7/2,S7<=T7/2),AND(T7<=R7/2,T7<=S7/2)),"Плоские","") | X7: =IF(LARGE($R7:$T7,1)="","",IF(LARGE($R7:$T7,1)<=99,"10-99 мм",IF(LARGE($R7:$T7,1)<=199,"100-199 мм",IF(LARGE($R7:$T7,1)<=299,"200-299 мм",IF(LARGE($R7:$T7,1)<=399,"300-399 мм",IF(LARGE($R7:$T7,1)<=499,"400-499 мм",IF(LARGE($R7:$T7,1)<=599,"500-599 мм",IF(LARGE($R7:$T7,1)<=699,"600-699 мм",IF(LARGE($R7:$T7,1)<=999,"700-999 мм","1000+ мм"))))))))) -> 500-599 мм | Y7: =IF(LARGE($R7:$T7,2)="","",IF(LARGE($R7:$T7,2)<=99,"10-99 мм",IF(LARGE($R7:$T7,2)<=199,"100-199 мм",IF(LARGE($R7:$T7,2)<=299,"200-299 мм",IF(LARGE($R7:$T7,2)<=399,"300-399 мм",IF(LARGE($R7:$T7,2)<=499,"400-499 мм",IF(LARGE($R7:$T7,2)<=599,"500-599 мм",IF(LARGE($R7:$T7,2)<=699,"600-699 мм",IF(LARGE($R7:$T7,2)<=999,"700-999 мм","1000+ мм"))))))))) -> 500-599 мм | Z7: =IF(SMALL($R7:$T7,1)="","",IF(SMALL($R7:$T7,1)<=99,"10-99 мм",IF(SMALL($R7:$T7,1)<=199,"100-199 мм",IF(SMALL($R7:$T7,1)<=299,"200-299 мм",IF(SMALL($R7:$T7,1)<=399,"300-399 мм",IF(SMALL($R7:$T7,1)<=499,"400-499 мм",IF(SMALL($R7:$T7,1)<=599,"500-599 мм",IF(SMALL($R7:$T7,1)<=699,"600-699 мм",IF(SMALL($R7:$T7,1)<=999,"700-999 мм","1000+ мм"))))))))) -> 300-399 мм | AA7: =IF(G7="","",IF(G7="Л","Лист гофрокартона",IF(G7="КД","Крышка-дно",IF(G7="С","Самосборные",IF(G7="Ч","Четырехклапанные",IF(G7="А","Архивные","Неизвестно")))))) -> Четырехклапанные | AB7: 1.73 | AC7: =IF(O7="","",IF(O7<=1,"0-1 литров",IF(O7<=3,"2-3 литра",IF(O7<=5,"4-5 литра",IF(O7<=7,"6-7 литра",IF(O7<=9,"8-9 литров",IF(O7<=14,"10-14 литров",IF(O7<=19,"15-19 литров",IF(O7<=29,"20-29 литров",IF(O7<=49,"30-49 литров",IF(O7<=59,"50-59 литров",IF(O7<=70,"60-69 литров",IF(O7<=79,"70-79 литров",IF(O7<=89,"80-89 литров",IF(O7<=99,"90-99 литров",IF(O7<=200,"100-200 литров","200+ литров")))))))))))))))) -> 100-200 литров
A8: 1.3 | B8: =A8*1.2 -> 1.56 | C8: 8 | D8: У | E8: 280х220х500 | G8: Ч | H8: 0201 | I8: В | J8: х | K8: K7 | N8: =IF(D8="","",IF(LEFT(D8,1)="0",0,1)) -> 1 | O8: =ROUND(R8*S8*T8/1000000,2) -> 30.8 | P8: =IF(O8="","", IF(O8<1,"0,1-0,9 литров", IF(O8<2,"1-1,9 литра", IF(O8<3,"2-2,9 литра", IF(O8<4,"3-3,9 литра", IF(O8<6,"4-5,9 литра",IF(O8<8,"6-7,9 литра",IF(O8<10,"8-9,9 литров",IF(O8<15,"10-14,9 литров",IF(O8<20,"15-19,9 литров",IF(O8<30,"20-29 литров",IF(O8<50,"30-49 литров",IF(O8<60,"50-59 литров",IF(O8<70,"60-69 литров",IF(O8<80,"70-79 литров",IF(O8<90,"80-89 литров",IF(O8<100,"90-99 литров",IF(O8<200,"100-200 литров","200+ литров")))))))))))))))))) -> 30-49 литров | Q8: =IF(O8="","",IF(O8<1,"<1 л",IF(O8<2,"1-2 л",IF(O8<3,"2-3 л",IF(O8<5,"3-5 л",IF(O8<10,"5-10 л",IF(O8<20,"10-20 л",IF(O8<50,"20-50 л",IF(O8<100,"50-100 л","100+ л"))))))))) -> 20-50 л | R8: =IF(E8="","",--LEFT(E8,FIND("х",E8)-1)) -> 280 | S8: =IF(E8="","",--MID(E8,FIND("х",E8)+1,FIND("х",E8,FIND("х",E8)+1)-FIND("х",E8)-1)) -> 220 | T8: =IF(E8="","",--RIGHT(E8,LEN(E8)-FIND("х",E8,FIND("х",E8)+1))) -> 500 | U8: =(2*(R8+S8)+60)*(S8+T8+8)/1000000 -> 0.77168 | V8: =IF(OR(AND(R8>=2*S8,R8>=2*T8),AND(S8>=2*R8,S8>=2*T8),AND(T8>=2*R8,T8>=2*S8)),"Длинные","") | W8: =IF(OR(AND(R8<=S8/2,R8<=T8/2),AND(S8<=R8/2,S8<=T8/2),AND(T8<=R8/2,T8<=S8/2)),"Плоские","") | X8: =IF(LARGE($R8:$T8,1)="","",IF(LARGE($R8:$T8,1)<=99,"10-99 мм",IF(LARGE($R8:$T8,1)<=199,"100-199 мм",IF(LARGE($R8:$T8,1)<=299,"200-299 мм",IF(LARGE($R8:$T8,1)<=399,"300-399 мм",IF(LARGE($R8:$T8,1)<=499,"400-499 мм",IF(LARGE($R8:$T8,1)<=599,"500-599 мм",IF(LARGE($R8:$T8,1)<=699,"600-699 мм",IF(LARGE($R8:$T8,1)<=999,"700-999 мм","1000+ мм"))))))))) -> 500-599 мм | Y8: =IF(LARGE($R8:$T8,2)="","",IF(LARGE($R8:$T8,2)<=99,"10-99 мм",IF(LARGE($R8:$T8,2)<=199,"100-199 мм",IF(LARGE($R8:$T8,2)<=299,"200-299 мм",IF(LARGE($R8:$T8,2)<=399,"300-399 мм",IF(LARGE($R8:$T8,2)<=499,"400-499 мм",IF(LARGE($R8:$T8,2)<=599,"500-599 мм",IF(LARGE($R8:$T8,2)<=699,"600-699 мм",IF(LARGE($R8:$T8,2)<=999,"700-999 мм","1000+ мм"))))))))) -> 200-299 мм | Z8: =IF(SMALL($R8:$T8,1)="","",IF(SMALL($R8:$T8,1)<=99,"10-99 мм",IF(SMALL($R8:$T8,1)<=199,"100-199 мм",IF(SMALL($R8:$T8,1)<=299,"200-299 мм",IF(SMALL($R8:$T8,1)<=399,"300-399 мм",IF(SMALL($R8:$T8,1)<=499,"400-499 мм",IF(SMALL($R8:$T8,1)<=599,"500-599 мм",IF(SMALL($R8:$T8,1)<=699,"600-699 мм",IF(SMALL($R8:$T8,1)<=999,"700-999 мм","1000+ мм"))))))))) -> 200-299 мм | AA8: =IF(G8="","",IF(G8="Л","Лист гофрокартона",IF(G8="КД","Крышка-дно",IF(G8="С","Самосборные",IF(G8="Ч","Четырехклапанные",IF(G8="А","Архивные","Неизвестно")))))) -> Четырехклапанные | AB8: 1.73 | AC8: =IF(O8="","",IF(O8<=1,"0-1 литров",IF(O8<=3,"2-3 литра",IF(O8<=5,"4-5 литра",IF(O8<=7,"6-7 литра",IF(O8<=9,"8-9 литров",IF(O8<=14,"10-14 литров",IF(O8<=19,"15-19 литров",IF(O8<=29,"20-29 литров",IF(O8<=49,"30-49 литров",IF(O8<=59,"50-59 литров",IF(O8<=70,"60-69 литров",IF(O8<=79,"70-79 литров",IF(O8<=89,"80-89 литров",IF(O8<=99,"90-99 литров",IF(O8<=200,"100-200 литров","200+ литров")))))))))))))))) -> 30-49 литров
A9: 1.25 | B9: =A9*1.2 -> 1.5 | C9: 9 | D9: У | E9: 405х55х605 | F9: 605х55х405 | G9: Ч | H9: 0215 | I9: В | J9: х | K9: K8 | N9: =IF(D9="","",IF(LEFT(D9,1)="0",0,1)) -> 1 | O9: =ROUND(R9*S9*T9/1000000,2) -> 13.48 | P9: =IF(O9="","", IF(O9<1,"0,1-0,9 литров", IF(O9<2,"1-1,9 литра", IF(O9<3,"2-2,9 литра", IF(O9<4,"3-3,9 литра", IF(O9<6,"4-5,9 литра",IF(O9<8,"6-7,9 литра",IF(O9<10,"8-9,9 литров",IF(O9<15,"10-14,9 литров",IF(O9<20,"15-19,9 литров",IF(O9<30,"20-29 литров",IF(O9<50,"30-49 литров",IF(O9<60,"50-59 литров",IF(O9<70,"60-69 литров",IF(O9<80,"70-79 литров",IF(O9<90,"80-89 литров",IF(O9<100,"90-99 литров",IF(O9<200,"100-200 литров","200+ литров")))))))))))))))))) -> 10-14,9 литров | Q9: =IF(O9="","",IF(O9<1,"<1 л",IF(O9<2,"1-2 л",IF(O9<3,"2-3 л",IF(O9<5,"3-5 л",IF(O9<10,"5-10 л",IF(O9<20,"10-20 л",IF(O9<50,"20-50 л",IF(O9<100,"50-100 л","100+ л"))))))))) -> 10-20 л | R9: =IF(E9="","",--LEFT(E9,FIND("х",E9)-1)) -> 405 | S9: =IF(E9="","",--MID(E9,FIND("х",E9)+1,FIND("х",E9,FIND("х",E9)+1)-FIND("х",E9)-1)) -> 55 | T9: =IF(E9="","",--RIGHT(E9,LEN(E9)-FIND("х",E9,FIND("х",E9)+1))) -> 605 | U9: =(2*(R9+S9)+60)*(S9+T9+8)/1000000 -> 0.65464 | V9: =IF(OR(AND(R9>=2*S9,R9>=2*T9),AND(S9>=2*R9,S9>=2*T9),AND(T9>=2*R9,T9>=2*S9)),"Длинные","") | W9: =IF(OR(AND(R9<=S9/2,R9<=T9/2),AND(S9<=R9/2,S9<=T9/2),AND(T9<=R9/2,T9<=S9/2)),"Плоские","") -> Плоские | X9: =IF(LARGE($R9:$T9,1)="","",IF(LARGE($R9:$T9,1)<=99,"10-99 мм",IF(LARGE($R9:$T9,1)<=199,"100-199 мм",IF(LARGE($R9:$T9,1)<=299,"200-299 мм",IF(LARGE($R9:$T9,1)<=399,"300-399 мм",IF(LARGE($R9:$T9,1)<=499,"400-499 мм",IF(LARGE($R9:$T9,1)<=599,"500-599 мм",IF(LARGE($R9:$T9,1)<=699,"600-699 мм",IF(LARGE($R9:$T9,1)<=999,"700-999 мм","1000+ мм"))))))))) -> 600-699 мм | Y9: =IF(LARGE($R9:$T9,2)="","",IF(LARGE($R9:$T9,2)<=99,"10-99 мм",IF(LARGE($R9:$T9,2)<=199,"100-199 мм",IF(LARGE($R9:$T9,2)<=299,"200-299 мм",IF(LARGE($R9:$T9,2)<=399,"300-399 мм",IF(LARGE($R9:$T9,2)<=499,"400-499 мм",IF(LARGE($R9:$T9,2)<=599,"500-599 мм",IF(LARGE($R9:$T9,2)<=699,"600-699 мм",IF(LARGE($R9:$T9,2)<=999,"700-999 мм","1000+ мм"))))))))) -> 400-499 мм | Z9: =IF(SMALL($R9:$T9,1)="","",IF(SMALL($R9:$T9,1)<=99,"10-99 мм",IF(SMALL($R9:$T9,1)<=199,"100-199 мм",IF(SMALL($R9:$T9,1)<=299,"200-299 мм",IF(SMALL($R9:$T9,1)<=399,"300-399 мм",IF(SMALL($R9:$T9,1)<=499,"400-499 мм",IF(SMALL($R9:$T9,1)<=599,"500-599 мм",IF(SMALL($R9:$T9,1)<=699,"600-699 мм",IF(SMALL($R9:$T9,1)<=999,"700-999 мм","1000+ мм"))))))))) -> 10-99 мм | AA9: =IF(G9="","",IF(G9="Л","Лист гофрокартона",IF(G9="КД","Крышка-дно",IF(G9="С","Самосборные",IF(G9="Ч","Четырехклапанные",IF(G9="А","Архивные","Неизвестно")))))) -> Четырехклапанные | AB9: 1.73 | AC9: =IF(O9="","",IF(O9<=1,"0-1 литров",IF(O9<=3,"2-3 литра",IF(O9<=5,"4-5 литра",IF(O9<=7,"6-7 литра",IF(O9<=9,"8-9 литров",IF(O9<=14,"10-14 литров",IF(O9<=19,"15-19 литров",IF(O9<=29,"20-29 литров",IF(O9<=49,"30-49 литров",IF(O9<=59,"50-59 литров",IF(O9<=70,"60-69 литров",IF(O9<=79,"70-79 литров",IF(O9<=89,"80-89 литров",IF(O9<=99,"90-99 литров",IF(O9<=200,"100-200 литров","200+ литров")))))))))))))))) -> 10-14 литров
A10: 1.09 | B10: =A10*1.2 -> 1.308 | C10: 10 | D10: У | E10: 160х150х800 | G10: Ч | H10: 0201 | I10: В | J10: х | K10: K9 | N10: =IF(D10="","",IF(LEFT(D10,1)="0",0,1)) -> 1 | O10: =ROUND(R10*S10*T10/1000000,2) -> 19.2 | P10: =IF(O10="","", IF(O10<1,"0,1-0,9 литров", IF(O10<2,"1-1,9 литра", IF(O10<3,"2-2,9 литра", IF(O10<4,"3-3,9 литра", IF(O10<6,"4-5,9 литра",IF(O10<8,"6-7,9 литра",IF(O10<10,"8-9,9 литров",IF(O10<15,"10-14,9 литров",IF(O10<20,"15-19,9 литров",IF(O10<30,"20-29 литров",IF(O10<50,"30-49 литров",IF(O10<60,"50-59 литров",IF(O10<70,"60-69 литров",IF(O10<80,"70-79 литров",IF(O10<90,"80-89 литров",IF(O10<100,"90-99 литров",IF(O10<200,"100-200 литров","200+ литров")))))))))))))))))) -> 15-19,9 литров | Q10: =IF(O10="","",IF(O10<1,"<1 л",IF(O10<2,"1-2 л",IF(O10<3,"2-3 л",IF(O10<5,"3-5 л",IF(O10<10,"5-10 л",IF(O10<20,"10-20 л",IF(O10<50,"20-50 л",IF(O10<100,"50-100 л","100+ л"))))))))) -> 10-20 л | R10: =IF(E10="","",--LEFT(E10,FIND("х",E10)-1)) -> 160 | S10: =IF(E10="","",--MID(E10,FIND("х",E10)+1,FIND("х",E10,FIND("х",E10)+1)-FIND("х",E10)-1)) -> 150 | T10: =IF(E10="","",--RIGHT(E10,LEN(E10)-FIND("х",E10,FIND("х",E10)+1))) -> 800 | U10: =(2*(R10+S10)+60)*(S10+T10+8)/1000000 -> 0.65144 | V10: =IF(OR(AND(R10>=2*S10,R10>=2*T10),AND(S10>=2*R10,S10>=2*T10),AND(T10>=2*R10,T10>=2*S10)),"Длинные","") -> Длинные | W10: =IF(OR(AND(R10<=S10/2,R10<=T10/2),AND(S10<=R10/2,S10<=T10/2),AND(T10<=R10/2,T10<=S10/2)),"Плоские","") | X10: =IF(LARGE($R10:$T10,1)="","",IF(LARGE($R10:$T10,1)<=99,"10-99 мм",IF(LARGE($R10:$T10,1)<=199,"100-199 мм",IF(LARGE($R10:$T10,1)<=299,"200-299 мм",IF(LARGE($R10:$T10,1)<=399,"300-399 мм",IF(LARGE($R10:$T10,1)<=499,"400-499 мм",IF(LARGE($R10:$T10,1)<=599,"500-599 мм",IF(LARGE($R10:$T10,1)<=699,"600-699 мм",IF(LARGE($R10:$T10,1)<=999,"700-999 мм","1000+ мм"))))))))) -> 700-999 мм | Y10: =IF(LARGE($R10:$T10,2)="","",IF(LARGE($R10:$T10,2)<=99,"10-99 мм",IF(LARGE($R10:$T10,2)<=199,"100-199 мм",IF(LARGE($R10:$T10,2)<=299,"200-299 мм",IF(LARGE($R10:$T10,2)<=399,"300-399 мм",IF(LARGE($R10:$T10,2)<=499,"400-499 мм",IF(LARGE($R10:$T10,2)<=599,"500-599 мм",IF(LARGE($R10:$T10,2)<=699,"600-699 мм",IF(LARGE($R10:$T10,2)<=999,"700-999 мм","1000+ мм"))))))))) -> 100-199 мм | Z10: =IF(SMALL($R10:$T10,1)="","",IF(SMALL($R10:$T10,1)<=99,"10-99 мм",IF(SMALL($R10:$T10,1)<=199,"100-199 мм",IF(SMALL($R10:$T10,1)<=299,"200-299 мм",IF(SMALL($R10:$T10,1)<=399,"300-399 мм",IF(SMALL($R10:$T10,1)<=499,"400-499 мм",IF(SMALL($R10:$T10,1)<=599,"500-599 мм",IF(SMALL($R10:$T10,1)<=699,"600-699 мм",IF(SMALL($R10:$T10,1)<=999,"700-999 мм","1000+ мм"))))))))) -> 100-199 мм | AA10: =IF(G10="","",IF(G10="Л","Лист гофрокартона",IF(G10="КД","Крышка-дно",IF(G10="С","Самосборные",IF(G10="Ч","Четырехклапанные",IF(G10="А","Архивные","Неизвестно")))))) -> Четырехклапанные | AB10: 1.73 | AC10: =IF(O10="","",IF(O10<=1,"0-1 литров",IF(O10<=3,"2-3 литра",IF(O10<=5,"4-5 литра",IF(O10<=7,"6-7 литра",IF(O10<=9,"8-9 литров",IF(O10<=14,"10-14 литров",IF(O10<=19,"15-19 литров",IF(O10<=29,"20-29 литров",IF(O10<=49,"30-49 литров",IF(O10<=59,"50-59 литров",IF(O10<=70,"60-69 литров",IF(O10<=79,"70-79 литров",IF(O10<=89,"80-89 литров",IF(O10<=99,"90-99 литров",IF(O10<=200,"100-200 литров","200+ литров")))))))))))))))) -> 20-29 литров
A11: 1.9 | B11: =A11*1.2 -> 2.28 | C11: 11 | D11: У | E11: 870х510х35 | G11: Ч | H11: 0401 | I11: В | J11: х | K11: K10 | N11: =IF(D11="","",IF(LEFT(D11,1)="0",0,1)) -> 1 | O11: =ROUND(R11*S11*T11/1000000,2) -> 15.53 | P11: =IF(O11="","", IF(O11<1,"0,1-0,9 литров", IF(O11<2,"1-1,9 литра", IF(O11<3,"2-2,9 литра", IF(O11<4,"3-3,9 литра", IF(O11<6,"4-5,9 литра",IF(O11<8,"6-7,9 литра",IF(O11<10,"8-9,9 литров",IF(O11<15,"10-14,9 литров",IF(O11<20,"15-19,9 литров",IF(O11<30,"20-29 литров",IF(O11<50,"30-49 литров",IF(O11<60,"50-59 литров",IF(O11<70,"60-69 литров",IF(O11<80,"70-79 литров",IF(O11<90,"80-89 литров",IF(O11<100,"90-99 литров",IF(O11<200,"100-200 литров","200+ литров")))))))))))))))))) -> 15-19,9 литров | Q11: =IF(O11="","",IF(O11<1,"<1 л",IF(O11<2,"1-2 л",IF(O11<3,"2-3 л",IF(O11<5,"3-5 л",IF(O11<10,"5-10 л",IF(O11<20,"10-20 л",IF(O11<50,"20-50 л",IF(O11<100,"50-100 л","100+ л"))))))))) -> 10-20 л | R11: =IF(E11="","",--LEFT(E11,FIND("х",E11)-1)) -> 870 | S11: =IF(E11="","",--MID(E11,FIND("х",E11)+1,FIND("х",E11,FIND("х",E11)+1)-FIND("х",E11)-1)) -> 510 | T11: =IF(E11="","",--RIGHT(E11,LEN(E11)-FIND("х",E11,FIND("х",E11)+1))) -> 35 | U11: =(2*(R11+S11)+60)*(S11+T11+8)/1000000 -> 1.55946 | V11: =IF(OR(AND(R11>=2*S11,R11>=2*T11),AND(S11>=2*R11,S11>=2*T11),AND(T11>=2*R11,T11>=2*S11)),"Длинные","") | W11: =IF(OR(AND(R11<=S11/2,R11<=T11/2),AND(S11<=R11/2,S11<=T11/2),AND(T11<=R11/2,T11<=S11/2)),"Плоские","") -> Плоские | X11: =IF(LARGE($R11:$T11,1)="","",IF(LARGE($R11:$T11,1)<=99,"10-99 мм",IF(LARGE($R11:$T11,1)<=199,"100-199 мм",IF(LARGE($R11:$T11,1)<=299,"200-299 мм",IF(LARGE($R11:$T11,1)<=399,"300-399 мм",IF(LARGE($R11:$T11,1)<=499,"400-499 мм",IF(LARGE($R11:$T11,1)<=599,"500-599 мм",IF(LARGE($R11:$T11,1)<=699,"600-699 мм",IF(LARGE($R11:$T11,1)<=999,"700-999 мм","1000+ мм"))))))))) -> 700-999 мм | Y11: =IF(LARGE($R11:$T11,2)="","",IF(LARGE($R11:$T11,2)<=99,"10-99 мм",IF(LARGE($R11:$T11,2)<=199,"100-199 мм",IF(LARGE($R11:$T11,2)<=299,"200-299 мм",IF(LARGE($R11:$T11,2)<=399,"300-399 мм",IF(LARGE($R11:$T11,2)<=499,"400-499 мм",IF(LARGE($R11:$T11,2)<=599,"500-599 мм",IF(LARGE($R11:$T11,2)<=699,"600-699 мм",IF(LARGE($R11:$T11,2)<=999,"700-999 мм","1000+ мм"))))))))) -> 500-599 мм | Z11: =IF(SMALL($R11:$T11,1)="","",IF(SMALL($R11:$T11,1)<=99,"10-99 мм",IF(SMALL($R11:$T11,1)<=199,"100-199 мм",IF(SMALL($R11:$T11,1)<=299,"200-299 мм",IF(SMALL($R11:$T11,1)<=399,"300-399 мм",IF(SMALL($R11:$T11,1)<=499,"400-499 мм",IF(SMALL($R11:$T11,1)<=599,"500-599 мм",IF(SMALL($R11:$T11,1)<=699,"600-699 мм",IF(SMALL($R11:$T11,1)<=999,"700-999 мм","1000+ мм"))))))))) -> 10-99 мм | AA11: =IF(G11="","",IF(G11="Л","Лист гофрокартона",IF(G11="КД","Крышка-дно",IF(G11="С","Самосборные",IF(G11="Ч","Четырехклапанные",IF(G11="А","Архивные","Неизвестно")))))) -> Четырехклапанные | AB11: 1.73 | AC11: =IF(O11="","",IF(O11<=1,"0-1 литров",IF(O11<=3,"2-3 литра",IF(O11<=5,"4-5 литра",IF(O11<=7,"6-7 литра",IF(O11<=9,"8-9 литров",IF(O11<=14,"10-14 литров",IF(O11<=19,"15-19 литров",IF(O11<=29,"20-29 литров",IF(O11<=49,"30-49 литров",IF(O11<=59,"50-59 литров",IF(O11<=70,"60-69 литров",IF(O11<=79,"70-79 литров",IF(O11<=89,"80-89 литров",IF(O11<=99,"90-99 литров",IF(O11<=200,"100-200 литров","200+ литров")))))))))))))))) -> 15-19 литров
A12: 1.71 | B12: =A12*1.2 -> 2.052 | C12: 12 | D12: У | E12: 400х400х200 | G12: Ч | H12: 0201 | I12: В | J12: х | K12: K11 | N12: =IF(D12="","",IF(LEFT(D12,1)="0",0,1)) -> 1 | O12: =ROUND(R12*S12*T12/1000000,2) -> 32 | P12: =IF(O12="","", IF(O12<1,"0,1-0,9 литров", IF(O12<2,"1-1,9 литра", IF(O12<3,"2-2,9 литра", IF(O12<4,"3-3,9 литра", IF(O12<6,"4-5,9 литра",IF(O12<8,"6-7,9 литра",IF(O12<10,"8-9,9 литров",IF(O12<15,"10-14,9 литров",IF(O12<20,"15-19,9 литров",IF(O12<30,"20-29 литров",IF(O12<50,"30-49 литров",IF(O12<60,"50-59 литров",IF(O12<70,"60-69 литров",IF(O12<80,"70-79 литров",IF(O12<90,"80-89 литров",IF(O12<100,"90-99 литров",IF(O12<200,"100-200 литров","200+ литров")))))))))))))))))) -> 30-49 литров | Q12: =IF(O12="","",IF(O12<1,"<1 л",IF(O12<2,"1-2 л",IF(O12<3,"2-3 л",IF(O12<5,"3-5 л",IF(O12<10,"5-10 л",IF(O12<20,"10-20 л",IF(O12<50,"20-50 л",IF(O12<100,"50-100 л","100+ л"))))))))) -> 20-50 л | R12: =IF(E12="","",--LEFT(E12,FIND("х",E12)-1)) -> 400 | S12: =IF(E12="","",--MID(E12,FIND("х",E12)+1,FIND("х",E12,FIND("х",E12)+1)-FIND("х",E12)-1)) -> 400 | T12: =IF(E12="","",--RIGHT(E12,LEN(E12)-FIND("х",E12,FIND("х",E12)+1))) -> 200 | U12: =(2*(R12+S12)+60)*(S12+T12+8)/1000000 -> 1.00928 | V12: =IF(OR(AND(R12>=2*S12,R12>=2*T12),AND(S12>=2*R12,S12>=2*T12),AND(T12>=2*R12,T12>=2*S12)),"Длинные","") | W12: =IF(OR(AND(R12<=S12/2,R12<=T12/2),AND(S12<=R12/2,S12<=T12/2),AND(T12<=R12/2,T12<=S12/2)),"Плоские","") -> Плоские | X12: =IF(LARGE($R12:$T12,1)="","",IF(LARGE($R12:$T12,1)<=99,"10-99 мм",IF(LARGE($R12:$T12,1)<=199,"100-199 мм",IF(LARGE($R12:$T12,1)<=299,"200-299 мм",IF(LARGE($R12:$T12,1)<=399,"300-399 мм",IF(LARGE($R12:$T12,1)<=499,"400-499 мм",IF(LARGE($R12:$T12,1)<=599,"500-599 мм",IF(LARGE($R12:$T12,1)<=699,"600-699 мм",IF(LARGE($R12:$T12,1)<=999,"700-999 мм","1000+ мм"))))))))) -> 400-499 мм | Y12: =IF(LARGE($R12:$T12,2)="","",IF(LARGE($R12:$T12,2)<=99,"10-99 мм",IF(LARGE($R12:$T12,2)<=199,"100-199 мм",IF(LARGE($R12:$T12,2)<=299,"200-299 мм",IF(LARGE($R12:$T12,2)<=399,"300-399 мм",IF(LARGE($R12:$T12,2)<=499,"400-499 мм",IF(LARGE($R12:$T12,2)<=599,"500-599 мм",IF(LARGE($R12:$T12,2)<=699,"600-699 мм",IF(LARGE($R12:$T12,2)<=999,"700-999 мм","1000+ мм"))))))))) -> 400-499 мм | Z12: =IF(SMALL($R12:$T12,1)="","",IF(SMALL($R12:$T12,1)<=99,"10-99 мм",IF(SMALL($R12:$T12,1)<=199,"100-199 мм",IF(SMALL($R12:$T12,1)<=299,"200-299 мм",IF(SMALL($R12:$T12,1)<=399,"300-399 мм",IF(SMALL($R12:$T12,1)<=499,"400-499 мм",IF(SMALL($R12:$T12,1)<=599,"500-599 мм",IF(SMALL($R12:$T12,1)<=699,"600-699 мм",IF(SMALL($R12:$T12,1)<=999,"700-999 мм","1000+ мм"))))))))) -> 200-299 мм | AA12: =IF(G12="","",IF(G12="Л","Лист гофрокартона",IF(G12="КД","Крышка-дно",IF(G12="С","Самосборные",IF(G12="Ч","Четырехклапанные",IF(G12="А","Архивные","Неизвестно")))))) -> Четырехклапанные | AB12: 1.73 | AC12: =IF(O12="","",IF(O12<=1,"0-1 литров",IF(O12<=3,"2-3 литра",IF(O12<=5,"4-5 литра",IF(O12<=7,"6-7 литра",IF(O12<=9,"8-9 литров",IF(O12<=14,"10-14 литров",IF(O12<=19,"15-19 литров",IF(O12<=29,"20-29 литров",IF(O12<=49,"30-49 литров",IF(O12<=59,"50-59 литров",IF(O12<=70,"60-69 литров",IF(O12<=79,"70-79 литров",IF(O12<=89,"80-89 литров",IF(O12<=99,"90-99 литров",IF(O12<=200,"100-200 литров","200+ литров")))))))))))))))) -> 30-49 литров
A13: 2.18 | B13: =A13*1.2 -> 2.616 | C13: 13 | D13: У | E13: 400х400х400 | G13: Ч | H13: 0201 | I13: В | J13: х | K13: K12 | N13: =IF(D13="","",IF(LEFT(D13,1)="0",0,1)) -> 1 | O13: =ROUND(R13*S13*T13/1000000,2) -> 64 | P13: =IF(O13="","", IF(O13<1,"0,1-0,9 литров", IF(O13<2,"1-1,9 литра", IF(O13<3,"2-2,9 литра", IF(O13<4,"3-3,9 литра", IF(O13<6,"4-5,9 литра",IF(O13<8,"6-7,9 литра",IF(O13<10,"8-9,9 литров",IF(O13<15,"10-14,9 литров",IF(O13<20,"15-19,9 литров",IF(O13<30,"20-29 литров",IF(O13<50,"30-49 литров",IF(O13<60,"50-59 литров",IF(O13<70,"60-69 литров",IF(O13<80,"70-79 литров",IF(O13<90,"80-89 литров",IF(O13<100,"90-99 литров",IF(O13<200,"100-200 литров","200+ литров")))))))))))))))))) -> 60-69 литров | Q13: =IF(O13="","",IF(O13<1,"<1 л",IF(O13<2,"1-2 л",IF(O13<3,"2-3 л",IF(O13<5,"3-5 л",IF(O13<10,"5-10 л",IF(O13<20,"10-20 л",IF(O13<50,"20-50 л",IF(O13<100,"50-100 л","100+ л"))))))))) -> 50-100 л | R13: =IF(E13="","",--LEFT(E13,FIND("х",E13)-1)) -> 400 | S13: =IF(E13="","",--MID(E13,FIND("х",E13)+1,FIND("х",E13,FIND("х",E13)+1)-FIND("х",E13)-1)) -> 400 | T13: =IF(E13="","",--RIGHT(E13,LEN(E13)-FIND("х",E13,FIND("х",E13)+1))) -> 400 | U13: =(2*(R13+S13)+60)*(S13+T13+8)/1000000 -> 1.34128 | V13: =IF(OR(AND(R13>=2*S13,R13>=2*T13),AND(S13>=2*R13,S13>=2*T13),AND(T13>=2*R13,T13>=2*S13)),"Длинные","") | W13: =IF(OR(AND(R13<=S13/2,R13<=T13/2),AND(S13<=R13/2,S13<=T13/2),AND(T13<=R13/2,T13<=S13/2)),"Плоские","") | X13: =IF(LARGE($R13:$T13,1)="","",IF(LARGE($R13:$T13,1)<=99,"10-99 мм",IF(LARGE($R13:$T13,1)<=199,"100-199 мм",IF(LARGE($R13:$T13,1)<=299,"200-299 мм",IF(LARGE($R13:$T13,1)<=399,"300-399 мм",IF(LARGE($R13:$T13,1)<=499,"400-499 мм",IF(LARGE($R13:$T13,1)<=599,"500-599 мм",IF(LARGE($R13:$T13,1)<=699,"600-699 мм",IF(LARGE($R13:$T13,1)<=999,"700-999 мм","1000+ мм"))))))))) -> 400-499 мм | Y13: =IF(LARGE($R13:$T13,2)="","",IF(LARGE($R13:$T13,2)<=99,"10-99 мм",IF(LARGE($R13:$T13,2)<=199,"100-199 мм",IF(LARGE($R13:$T13,2)<=299,"200-299 мм",IF(LARGE($R13:$T13,2)<=399,"300-399 мм",IF(LARGE($R13:$T13,2)<=499,"400-499 мм",IF(LARGE($R13:$T13,2)<=599,"500-599 мм",IF(LARGE($R13:$T13,2)<=699,"600-699 мм",IF(LARGE($R13:$T13,2)<=999,"700-999 мм","1000+ мм"))))))))) -> 400-499 мм | Z13: =IF(SMALL($R13:$T13,1)="","",IF(SMALL($R13:$T13,1)<=99,"10-99 мм",IF(SMALL($R13:$T13,1)<=199,"100-199 мм",IF(SMALL($R13:$T13,1)<=299,"200-299 мм",IF(SMALL($R13:$T13,1)<=399,"300-399 мм",IF(SMALL($R13:$T13,1)<=499,"400-499 мм",IF(SMALL($R13:$T13,1)<=599,"500-599 мм",IF(SMALL($R13:$T13,1)<=699,"600-699 мм",IF(SMALL($R13:$T13,1)<=999,"700-999 мм","1000+ мм"))))))))) -> 400-499 мм | AA13: =IF(G13="","",IF(G13="Л","Лист гофрокартона",IF(G13="КД","Крышка-дно",IF(G13="С","Самосборные",IF(G13="Ч","Четырехклапанные",IF(G13="А","Архивные","Неизвестно")))))) -> Четырехклапанные | AB13: 1.73 | AC13: =IF(O13="","",IF(O13<=1,"0-1 литров",IF(O13<=3,"2-3 литра",IF(O13<=5,"4-5 литра",IF(O13<=7,"6-7 литра",IF(O13<=9,"8-9 литров",IF(O13<=14,"10-14 литров",IF(O13<=19,"15-19 литров",IF(O13<=29,"20-29 литров",IF(O13<=49,"30-49 литров",IF(O13<=59,"50-59 литров",IF(O13<=70,"60-69 литров",IF(O13<=79,"70-79 литров",IF(O13<=89,"80-89 литров",IF(O13<=99,"90-99 литров",IF(O13<=200,"100-200 литров","200+ литров")))))))))))))))) -> 60-69 литров
A14: 0.13 | B14: =A14*1.2 -> 0.156 | C14: 14 | D14: У | E14: 50х50х145 | G14: С | H14: 0215 | I14: Е | J14: х | K14: K14 | N14: =IF(D14="","",IF(LEFT(D14,1)="0",0,1)) -> 1 | O14: =ROUND(R14*S14*T14/1000000,2) -> 0.36 | P14: =IF(O14="","", IF(O14<1,"0,1-0,9 литров", IF(O14<2,"1-1,9 литра", IF(O14<3,"2-2,9 литра", IF(O14<4,"3-3,9 литра", IF(O14<6,"4-5,9 литра",IF(O14<8,"6-7,9 литра",IF(O14<10,"8-9,9 литров",IF(O14<15,"10-14,9 литров",IF(O14<20,"15-19,9 литров",IF(O14<30,"20-29 литров",IF(O14<50,"30-49 литров",IF(O14<60,"50-59 литров",IF(O14<70,"60-69 литров",IF(O14<80,"70-79 литров",IF(O14<90,"80-89 литров",IF(O14<100,"90-99 литров",IF(O14<200,"100-200 литров","200+ литров")))))))))))))))))) -> 0,1-0,9 литров | Q14: =IF(O14="","",IF(O14<1,"<1 л",IF(O14<2,"1-2 л",IF(O14<3,"2-3 л",IF(O14<5,"3-5 л",IF(O14<10,"5-10 л",IF(O14<20,"10-20 л",IF(O14<50,"20-50 л",IF(O14<100,"50-100 л","100+ л"))))))))) -> <1 л | R14: =IF(E14="","",--LEFT(E14,FIND("х",E14)-1)) -> 50 | S14: =IF(E14="","",--MID(E14,FIND("х",E14)+1,FIND("х",E14,FIND("х",E14)+1)-FIND("х",E14)-1)) -> 50 | T14: =IF(E14="","",--RIGHT(E14,LEN(E14)-FIND("х",E14,FIND("х",E14)+1))) -> 145 | U14: =(2*(R14+S14)+60)*(S14+T14+8)/1000000 -> 0.05278 | V14: =IF(OR(AND(R14>=2*S14,R14>=2*T14),AND(S14>=2*R14,S14>=2*T14),AND(T14>=2*R14,T14>=2*S14)),"Длинные","") -> Длинные | W14: =IF(OR(AND(R14<=S14/2,R14<=T14/2),AND(S14<=R14/2,S14<=T14/2),AND(T14<=R14/2,T14<=S14/2)),"Плоские","") | X14: =IF(LARGE($R14:$T14,1)="","",IF(LARGE($R14:$T14,1)<=99,"10-99 мм",IF(LARGE($R14:$T14,1)<=199,"100-199 мм",IF(LARGE($R14:$T14,1)<=299,"200-299 мм",IF(LARGE($R14:$T14,1)<=399,"300-399 мм",IF(LARGE($R14:$T14,1)<=499,"400-499 мм",IF(LARGE($R14:$T14,1)<=599,"500-599 мм",IF(LARGE($R14:$T14,1)<=699,"600-699 мм",IF(LARGE($R14:$T14,1)<=999,"700-999 мм","1000+ мм"))))))))) -> 100-199 мм | Y14: =IF(LARGE($R14:$T14,2)="","",IF(LARGE($R14:$T14,2)<=99,"10-99 мм",IF(LARGE($R14:$T14,2)<=199,"100-199 мм",IF(LARGE($R14:$T14,2)<=299,"200-299 мм",IF(LARGE($R14:$T14,2)<=399,"300-399 мм",IF(LARGE($R14:$T14,2)<=499,"400-499 мм",IF(LARGE($R14:$T14,2)<=599,"500-599 мм",IF(LARGE($R14:$T14,2)<=699,"600-699 мм",IF(LARGE($R14:$T14,2)<=999,"700-999 мм","1000+ мм"))))))))) -> 10-99 мм | Z14: =IF(SMALL($R14:$T14,1)="","",IF(SMALL($R14:$T14,1)<=99,"10-99 мм",IF(SMALL($R14:$T14,1)<=199,"100-199 мм",IF(SMALL($R14:$T14,1)<=299,"200-299 мм",IF(SMALL($R14:$T14,1)<=399,"300-399 мм",IF(SMALL($R14:$T14,1)<=499,"400-499 мм",IF(SMALL($R14:$T14,1)<=599,"500-599 мм",IF(SMALL($R14:$T14,1)<=699,"600-699 мм",IF(SMALL($R14:$T14,1)<=999,"700-999 мм","1000+ мм"))))))))) -> 10-99 мм | AA14: =IF(G14="","",IF(G14="Л","Лист гофрокартона",IF(G14="КД","Крышка-дно",IF(G14="С","Самосборные",IF(G14="Ч","Четырехклапанные",IF(G14="А","Архивные","Неизвестно")))))) -> Самосборные | AB14: 1.73 | AC14: =IF(O14="","",IF(O14<=1,"0-1 литров",IF(O14<=3,"2-3 литра",IF(O14<=5,"4-5 литра",IF(O14<=7,"6-7 литра",IF(O14<=9,"8-9 литров",IF(O14<=14,"10-14 литров",IF(O14<=19,"15-19 литров",IF(O14<=29,"20-29 литров",IF(O14<=49,"30-49 литров",IF(O14<=59,"50-59 литров",IF(O14<=70,"60-69 литров",IF(O14<=79,"70-79 литров",IF(O14<=89,"80-89 литров",IF(O14<=99,"90-99 литров",IF(O14<=200,"100-200 литров","200+ литров")))))))))))))))) -> 0-1 литров
A15: 0.17 | B15: =A15*1.2 -> 0.204 | C15: 15 | D15: У | E15: 200х90х25 | G15: С | H15: 0427 | I15: Е | J15: х | K15: K15 | N15: =IF(D15="","",IF(LEFT(D15,1)="0",0,1)) -> 1 | O15: =ROUND(R15*S15*T15/1000000,2) -> 0.45 | P15: =IF(O15="","", IF(O15<1,"0,1-0,9 литров", IF(O15<2,"1-1,9 литра", IF(O15<3,"2-2,9 литра", IF(O15<4,"3-3,9 литра", IF(O15<6,"4-5,9 литра",IF(O15<8,"6-7,9 литра",IF(O15<10,"8-9,9 литров",IF(O15<15,"10-14,9 литров",IF(O15<20,"15-19,9 литров",IF(O15<30,"20-29 литров",IF(O15<50,"30-49 литров",IF(O15<60,"50-59 литров",IF(O15<70,"60-69 литров",IF(O15<80,"70-79 литров",IF(O15<90,"80-89 литров",IF(O15<100,"90-99 литров",IF(O15<200,"100-200 литров","200+ литров")))))))))))))))))) -> 0,1-0,9 литров | Q15: =IF(O15="","",IF(O15<1,"<1 л",IF(O15<2,"1-2 л",IF(O15<3,"2-3 л",IF(O15<5,"3-5 л",IF(O15<10,"5-10 л",IF(O15<20,"10-20 л",IF(O15<50,"20-50 л",IF(O15<100,"50-100 л","100+ л"))))))))) -> <1 л | R15: =IF(E15="","",--LEFT(E15,FIND("х",E15)-1)) -> 200 | S15: =IF(E15="","",--MID(E15,FIND("х",E15)+1,FIND("х",E15,FIND("х",E15)+1)-FIND("х",E15)-1)) -> 90 | T15: =IF(E15="","",--RIGHT(E15,LEN(E15)-FIND("х",E15,FIND("х",E15)+1))) -> 25 | U15: =(2*(R15+S15)+60)*(S15+T15+8)/1000000 -> 0.07872 | V15: =IF(OR(AND(R15>=2*S15,R15>=2*T15),AND(S15>=2*R15,S15>=2*T15),AND(T15>=2*R15,T15>=2*S15)),"Длинные","") -> Длинные | W15: =IF(OR(AND(R15<=S15/2,R15<=T15/2),AND(S15<=R15/2,S15<=T15/2),AND(T15<=R15/2,T15<=S15/2)),"Плоские","") -> Плоские | X15: =IF(LARGE($R15:$T15,1)="","",IF(LARGE($R15:$T15,1)<=99,"10-99 мм",IF(LARGE($R15:$T15,1)<=199,"100-199 мм",IF(LARGE($R15:$T15,1)<=299,"200-299 мм",IF(LARGE($R15:$T15,1)<=399,"300-399 мм",IF(LARGE($R15:$T15,1)<=499,"400-499 мм",IF(LARGE($R15:$T15,1)<=599,"500-599 мм",IF(LARGE($R15:$T15,1)<=699,"600-699 мм",IF(LARGE($R15:$T15,1)<=999,"700-999 мм","1000+ мм"))))))))) -> 200-299 мм | Y15: =IF(LARGE($R15:$T15,2)="","",IF(LARGE($R15:$T15,2)<=99,"10-99 мм",IF(LARGE($R15:$T15,2)<=199,"100-199 мм",IF(LARGE($R15:$T15,2)<=299,"200-299 мм",IF(LARGE($R15:$T15,2)<=399,"300-399 мм",IF(LARGE($R15:$T15,2)<=499,"400-499 мм",IF(LARGE($R15:$T15,2)<=599,"500-599 мм",IF(LARGE($R15:$T15,2)<=699,"600-699 мм",IF(LARGE($R15:$T15,2)<=999,"700-999 мм","1000+ мм"))))))))) -> 10-99 мм | Z15: =IF(SMALL($R15:$T15,1)="","",IF(SMALL($R15:$T15,1)<=99,"10-99 мм",IF(SMALL($R15:$T15,1)<=199,"100-199 мм",IF(SMALL($R15:$T15,1)<=299,"200-299 мм",IF(SMALL($R15:$T15,1)<=399,"300-399 мм",IF(SMALL($R15:$T15,1)<=499,"400-499 мм",IF(SMALL($R15:$T15,1)<=599,"500-599 мм",IF(SMALL($R15:$T15,1)<=699,"600-699 мм",IF(SMALL($R15:$T15,1)<=999,"700-999 мм","1000+ мм"))))))))) -> 10-99 мм | AA15: =IF(G15="","",IF(G15="Л","Лист гофрокартона",IF(G15="КД","Крышка-дно",IF(G15="С","Самосборные",IF(G15="Ч","Четырехклапанные",IF(G15="А","Архивные","Неизвестно")))))) -> Самосборные | AB15: 1.73 | AC15: =IF(O15="","",IF(O15<=1,"0-1 литров",IF(O15<=3,"2-3 литра",IF(O15<=5,"4-5 литра",IF(O15<=7,"6-7 литра",IF(O15<=9,"8-9 литров",IF(O15<=14,"10-14 литров",IF(O15<=19,"15-19 литров",IF(O15<=29,"20-29 литров",IF(O15<=49,"30-49 литров",IF(O15<=59,"50-59 литров",IF(O15<=70,"60-69 литров",IF(O15<=79,"70-79 литров",IF(O15<=89,"80-89 литров",IF(O15<=99,"90-99 литров",IF(O15<=200,"100-200 литров","200+ литров")))))))))))))))) -> 0-1 литров
A16: 0.54 | B16: =A16*1.2 -> 0.648 | C16: 16 | D16: У | E16: 250х100х320 | G16: Ч | H16: 0201 | I16: В | J16: х | K16: K16 | N16: =IF(D16="","",IF(LEFT(D16,1)="0",0,1)) -> 1 | O16: =ROUND(R16*S16*T16/1000000,2) -> 8 | P16: =IF(O16="","", IF(O16<1,"0,1-0,9 литров", IF(O16<2,"1-1,9 литра", IF(O16<3,"2-2,9 литра", IF(O16<4,"3-3,9 литра", IF(O16<6,"4-5,9 литра",IF(O16<8,"6-7,9 литра",IF(O16<10,"8-9,9 литров",IF(O16<15,"10-14,9 литров",IF(O16<20,"15-19,9 литров",IF(O16<30,"20-29 литров",IF(O16<50,"30-49 литров",IF(O16<60,"50-59 литров",IF(O16<70,"60-69 литров",IF(O16<80,"70-79 литров",IF(O16<90,"80-89 литров",IF(O16<100,"90-99 литров",IF(O16<200,"100-200 литров","200+ литров")))))))))))))))))) -> 8-9,9 литров | Q16: =IF(O16="","",IF(O16<1,"<1 л",IF(O16<2,"1-2 л",IF(O16<3,"2-3 л",IF(O16<5,"3-5 л",IF(O16<10,"5-10 л",IF(O16<20,"10-20 л",IF(O16<50,"20-50 л",IF(O16<100,"50-100 л","100+ л"))))))))) -> 5-10 л | R16: =IF(E16="","",--LEFT(E16,FIND("х",E16)-1)) -> 250 | S16: =IF(E16="","",--MID(E16,FIND("х",E16)+1,FIND("х",E16,FIND("х",E16)+1)-FIND("х",E16)-1)) -> 100 | T16: =IF(E16="","",--RIGHT(E16,LEN(E16)-FIND("х",E16,FIND("х",E16)+1))) -> 320 | U16: =(2*(R16+S16)+60)*(S16+T16+8)/1000000 -> 0.32528 | V16: =IF(OR(AND(R16>=2*S16,R16>=2*T16),AND(S16>=2*R16,S16>=2*T16),AND(T16>=2*R16,T16>=2*S16)),"Длинные","") | W16: =IF(OR(AND(R16<=S16/2,R16<=T16/2),AND(S16<=R16/2,S16<=T16/2),AND(T16<=R16/2,T16<=S16/2)),"Плоские","") -> Плоские | X16: =IF(LARGE($R16:$T16,1)="","",IF(LARGE($R16:$T16,1)<=99,"10-99 мм",IF(LARGE($R16:$T16,1)<=199,"100-199 мм",IF(LARGE($R16:$T16,1)<=299,"200-299 мм",IF(LARGE($R16:$T16,1)<=399,"300-399 мм",IF(LARGE($R16:$T16,1)<=499,"400-499 мм",IF(LARGE($R16:$T16,1)<=599,"500-599 мм",IF(LARGE($R16:$T16,1)<=699,"600-699 мм",IF(LARGE($R16:$T16,1)<=999,"700-999 мм","1000+ мм"))))))))) -> 300-399 мм | Y16: =IF(LARGE($R16:$T16,2)="","",IF(LARGE($R16:$T16,2)<=99,"10-99 мм",IF(LARGE($R16:$T16,2)<=199,"100-199 мм",IF(LARGE($R16:$T16,2)<=299,"200-299 мм",IF(LARGE($R16:$T16,2)<=399,"300-399 мм",IF(LARGE($R16:$T16,2)<=499,"400-499 мм",IF(LARGE($R16:$T16,2)<=599,"500-599 мм",IF(LARGE($R16:$T16,2)<=699,"600-699 мм",IF(LARGE($R16:$T16,2)<=999,"700-999 мм","1000+ мм"))))))))) -> 200-299 мм | Z16: =IF(SMALL($R16:$T16,1)="","",IF(SMALL($R16:$T16,1)<=99,"10-99 мм",IF(SMALL($R16:$T16,1)<=199,"100-199 мм",IF(SMALL($R16:$T16,1)<=299,"200-299 мм",IF(SMALL($R16:$T16,1)<=399,"300-399 мм",IF(SMALL($R16:$T16,1)<=499,"400-499 мм",IF(SMALL($R16:$T16,1)<=599,"500-599 мм",IF(SMALL($R16:$T16,1)<=699,"600-699 мм",IF(SMALL($R16:$T16,1)<=999,"700-999 мм","1000+ мм"))))))))) -> 100-199 мм | AA16: =IF(G16="","",IF(G16="Л","Лист гофрокартона",IF(G16="КД","Крышка-дно",IF(G16="С","Самосборные",IF(G16="Ч","Четырехклапанные",IF(G16="А","Архивные","Неизвестно")))))) -> Четырехклапанные | AB16: 1.73 | AC16: =IF(O16="","",IF(O16<=1,"0-1 литров",IF(O16<=3,"2-3 литра",IF(O16<=5,"4-5 литра",IF(O16<=7,"6-7 литра",IF(O16<=9,"8-9 литров",IF(O16<=14,"10-14 литров",IF(O16<=19,"15-19 литров",IF(O16<=29,"20-29 литров",IF(O16<=49,"30-49 литров",IF(O16<=59,"50-59 литров",IF(O16<=70,"60-69 литров",IF(O16<=79,"70-79 литров",IF(O16<=89,"80-89 литров",IF(O16<=99,"90-99 литров",IF(O16<=200,"100-200 литров","200+ литров")))))))))))))))) -> 8-9 литров
A17: 0.15 | B17: =A17*1.2 -> 0.18 | C17: 17 | D17: У | E17: 90х80х30 | G17: С | H17: 0427 | I17: Е | J17: х | K17: K17 | N17: =IF(D17="","",IF(LEFT(D17,1)="0",0,1)) -> 1 | O17: =ROUND(R17*S17*T17/1000000,2) -> 0.22 | P17: =IF(O17="","", IF(O17<1,"0,1-0,9 литров", IF(O17<2,"1-1,9 литра", IF(O17<3,"2-2,9 литра", IF(O17<4,"3-3,9 литра", IF(O17<6,"4-5,9 литра",IF(O17<8,"6-7,9 литра",IF(O17<10,"8-9,9 литров",IF(O17<15,"10-14,9 литров",IF(O17<20,"15-19,9 литров",IF(O17<30,"20-29 литров",IF(O17<50,"30-49 литров",IF(O17<60,"50-59 литров",IF(O17<70,"60-69 литров",IF(O17<80,"70-79 литров",IF(O17<90,"80-89 литров",IF(O17<100,"90-99 литров",IF(O17<200,"100-200 литров","200+ литров")))))))))))))))))) -> 0,1-0,9 литров | Q17: =IF(O17="","",IF(O17<1,"<1 л",IF(O17<2,"1-2 л",IF(O17<3,"2-3 л",IF(O17<5,"3-5 л",IF(O17<10,"5-10 л",IF(O17<20,"10-20 л",IF(O17<50,"20-50 л",IF(O17<100,"50-100 л","100+ л"))))))))) -> <1 л | R17: =IF(E17="","",--LEFT(E17,FIND("х",E17)-1)) -> 90 | S17: =IF(E17="","",--MID(E17,FIND("х",E17)+1,FIND("х",E17,FIND("х",E17)+1)-FIND("х",E17)-1)) -> 80 | T17: =IF(E17="","",--RIGHT(E17,LEN(E17)-FIND("х",E17,FIND("х",E17)+1))) -> 30 | U17: =(2*(R17+S17)+60)*(S17+T17+8)/1000000 -> 0.0472 | V17: =IF(OR(AND(R17>=2*S17,R17>=2*T17),AND(S17>=2*R17,S17>=2*T17),AND(T17>=2*R17,T17>=2*S17)),"Длинные","") | W17: =IF(OR(AND(R17<=S17/2,R17<=T17/2),AND(S17<=R17/2,S17<=T17/2),AND(T17<=R17/2,T17<=S17/2)),"Плоские","") -> Плоские | X17: =IF(LARGE($R17:$T17,1)="","",IF(LARGE($R17:$T17,1)<=99,"10-99 мм",IF(LARGE($R17:$T17,1)<=199,"100-199 мм",IF(LARGE($R17:$T17,1)<=299,"200-299 мм",IF(LARGE($R17:$T17,1)<=399,"300-399 мм",IF(LARGE($R17:$T17,1)<=499,"400-499 мм",IF(LARGE($R17:$T17,1)<=599,"500-599 мм",IF(LARGE($R17:$T17,1)<=699,"600-699 мм",IF(LARGE($R17:$T17,1)<=999,"700-999 мм","1000+ мм"))))))))) -> 10-99 мм | Y17: =IF(LARGE($R17:$T17,2)="","",IF(LARGE($R17:$T17,2)<=99,"10-99 мм",IF(LARGE($R17:$T17,2)<=199,"100-199 мм",IF(LARGE($R17:$T17,2)<=299,"200-299 мм",IF(LARGE($R17:$T17,2)<=399,"300-399 мм",IF(LARGE($R17:$T17,2)<=499,"400-499 мм",IF(LARGE($R17:$T17,2)<=599,"500-599 мм",IF(LARGE($R17:$T17,2)<=699,"600-699 мм",IF(LARGE($R17:$T17,2)<=999,"700-999 мм","1000+ мм"))))))))) -> 10-99 мм | Z17: =IF(SMALL($R17:$T17,1)="","",IF(SMALL($R17:$T17,1)<=99,"10-99 мм",IF(SMALL($R17:$T17,1)<=199,"100-199 мм",IF(SMALL($R17:$T17,1)<=299,"200-299 мм",IF(SMALL($R17:$T17,1)<=399,"300-399 мм",IF(SMALL($R17:$T17,1)<=499,"400-499 мм",IF(SMALL($R17:$T17,1)<=599,"500-599 мм",IF(SMALL($R17:$T17,1)<=699,"600-699 мм",IF(SMALL($R17:$T17,1)<=999,"700-999 мм","1000+ мм"))))))))) -> 10-99 мм | AA17: =IF(G17="","",IF(G17="Л","Лист гофрокартона",IF(G17="КД","Крышка-дно",IF(G17="С","Самосборные",IF(G17="Ч","Четырехклапанные",IF(G17="А","Архивные","Неизвестно")))))) -> Самосборные | AB17: 1.73 | AC17: =IF(O17="","",IF(O17<=1,"0-1 литров",IF(O17<=3,"2-3 литра",IF(O17<=5,"4-5 литра",IF(O17<=7,"6-7 литра",IF(O17<=9,"8-9 литров",IF(O17<=14,"10-14 литров",IF(O17<=19,"15-19 литров",IF(O17<=29,"20-29 литров",IF(O17<=49,"30-49 литров",IF(O17<=59,"50-59 литров",IF(O17<=70,"60-69 литров",IF(O17<=79,"70-79 литров",IF(O17<=89,"80-89 литров",IF(O17<=99,"90-99 литров",IF(O17<=200,"100-200 литров","200+ литров")))))))))))))))) -> 0-1 литров
A18: 0.28 | B18: =A18*1.2 -> 0.336 | C18: 18 | D18: У | E18: 65х65х40 | G18: С | H18: 0215 | I18: Е | J18: х | K18: K18 | N18: =IF(D18="","",IF(LEFT(D18,1)="0",0,1)) -> 1 | O18: =ROUND(R18*S18*T18/1000000,2) -> 0.17 | P18: =IF(O18="","", IF(O18<1,"0,1-0,9 литров", IF(O18<2,"1-1,9 литра", IF(O18<3,"2-2,9 литра", IF(O18<4,"3-3,9 литра", IF(O18<6,"4-5,9 литра",IF(O18<8,"6-7,9 литра",IF(O18<10,"8-9,9 литров",IF(O18<15,"10-14,9 литров",IF(O18<20,"15-19,9 литров",IF(O18<30,"20-29 литров",IF(O18<50,"30-49 литров",IF(O18<60,"50-59 литров",IF(O18<70,"60-69 литров",IF(O18<80,"70-79 литров",IF(O18<90,"80-89 литров",IF(O18<100,"90-99 литров",IF(O18<200,"100-200 литров","200+ литров")))))))))))))))))) -> 0,1-0,9 литров | Q18: =IF(O18="","",IF(O18<1,"<1 л",IF(O18<2,"1-2 л",IF(O18<3,"2-3 л",IF(O18<5,"3-5 л",IF(O18<10,"5-10 л",IF(O18<20,"10-20 л",IF(O18<50,"20-50 л",IF(O18<100,"50-100 л","100+ л"))))))))) -> <1 л | R18: =IF(E18="","",--LEFT(E18,FIND("х",E18)-1)) -> 65 | S18: =IF(E18="","",--MID(E18,FIND("х",E18)+1,FIND("х",E18,FIND("х",E18)+1)-FIND("х",E18)-1)) -> 65 | T18: =IF(E18="","",--RIGHT(E18,LEN(E18)-FIND("х",E18,FIND("х",E18)+1))) -> 40 | U18: =(2*(R18+S18)+60)*(S18+T18+8)/1000000 -> 0.03616 | V18: =IF(OR(AND(R18>=2*S18,R18>=2*T18),AND(S18>=2*R18,S18>=2*T18),AND(T18>=2*R18,T18>=2*S18)),"Длинные","") | W18: =IF(OR(AND(R18<=S18/2,R18<=T18/2),AND(S18<=R18/2,S18<=T18/2),AND(T18<=R18/2,T18<=S18/2)),"Плоские","") | X18: =IF(LARGE($R18:$T18,1)="","",IF(LARGE($R18:$T18,1)<=99,"10-99 мм",IF(LARGE($R18:$T18,1)<=199,"100-199 мм",IF(LARGE($R18:$T18,1)<=299,"200-299 мм",IF(LARGE($R18:$T18,1)<=399,"300-399 мм",IF(LARGE($R18:$T18,1)<=499,"400-499 мм",IF(LARGE($R18:$T18,1)<=599,"500-599 мм",IF(LARGE($R18:$T18,1)<=699,"600-699 мм",IF(LARGE($R18:$T18,1)<=999,"700-999 мм","1000+ мм"))))))))) -> 10-99 мм | Y18: =IF(LARGE($R18:$T18,2)="","",IF(LARGE($R18:$T18,2)<=99,"10-99 мм",IF(LARGE($R18:$T18,2)<=199,"100-199 мм",IF(LARGE($R18:$T18,2)<=299,"200-299 мм",IF(LARGE($R18:$T18,2)<=399,"300-399 мм",IF(LARGE($R18:$T18,2)<=499,"400-499 мм",IF(LARGE($R18:$T18,2)<=599,"500-599 мм",IF(LARGE($R18:$T18,2)<=699,"600-699 мм",IF(LARGE($R18:$T18,2)<=999,"700-999 мм","1000+ мм"))))))))) -> 10-99 мм | Z18: =IF(SMALL($R18:$T18,1)="","",IF(SMALL($R18:$T18,1)<=99,"10-99 мм",IF(SMALL($R18:$T18,1)<=199,"100-199 мм",IF(SMALL($R18:$T18,1)<=299,"200-299 мм",IF(SMALL($R18:$T18,1)<=399,"300-399 мм",IF(SMALL($R18:$T18,1)<=499,"400-499 мм",IF(SMALL($R18:$T18,1)<=599,"500-599 мм",IF(SMALL($R18:$T18,1)<=699,"600-699 мм",IF(SMALL($R18:$T18,1)<=999,"700-999 мм","1000+ мм"))))))))) -> 10-99 мм | AA18: =IF(G18="","",IF(G18="Л","Лист гофрокартона",IF(G18="КД","Крышка-дно",IF(G18="С","Самосборные",IF(G18="Ч","Четырехклапанные",IF(G18="А","Архивные","Неизвестно")))))) -> Самосборные | AB18: 1.73 | AC18: =IF(O18="","",IF(O18<=1,"0-1 литров",IF(O18<=3,"2-3 литра",IF(O18<=5,"4-5 литра",IF(O18<=7,"6-7 литра",IF(O18<=9,"8-9 литров",IF(O18<=14,"10-14 литров",IF(O18<=19,"15-19 литров",IF(O18<=29,"20-29 литров",IF(O18<=49,"30-49 литров",IF(O18<=59,"50-59 литров",IF(O18<=70,"60-69 литров",IF(O18<=79,"70-79 литров",IF(O18<=89,"80-89 литров",IF(O18<=99,"90-99 литров",IF(O18<=200,"100-200 литров","200+ литров")))))))))))))))) -> 0-1 литров
A19: 0.28 | B19: =A19*1.2 -> 0.336 | C19: 19 | D19: У | E19: 178х120х46 | G19: С | H19: 0426 | I19: Е | J19: х | K19: K19 | N19: =IF(D19="","",IF(LEFT(D19,1)="0",0,1)) -> 1 | O19: =ROUND(R19*S19*T19/1000000,2) -> 0.98 | P19: =IF(O19="","", IF(O19<1,"0,1-0,9 литров", IF(O19<2,"1-1,9 литра", IF(O19<3,"2-2,9 литра", IF(O19<4,"3-3,9 литра", IF(O19<6,"4-5,9 литра",IF(O19<8,"6-7,9 литра",IF(O19<10,"8-9,9 литров",IF(O19<15,"10-14,9 литров",IF(O19<20,"15-19,9 литров",IF(O19<30,"20-29 литров",IF(O19<50,"30-49 литров",IF(O19<60,"50-59 литров",IF(O19<70,"60-69 литров",IF(O19<80,"70-79 литров",IF(O19<90,"80-89 литров",IF(O19<100,"90-99 литров",IF(O19<200,"100-200 литров","200+ литров")))))))))))))))))) -> 0,1-0,9 литров | Q19: =IF(O19="","",IF(O19<1,"<1 л",IF(O19<2,"1-2 л",IF(O19<3,"2-3 л",IF(O19<5,"3-5 л",IF(O19<10,"5-10 л",IF(O19<20,"10-20 л",IF(O19<50,"20-50 л",IF(O19<100,"50-100 л","100+ л"))))))))) -> <1 л | R19: =IF(E19="","",--LEFT(E19,FIND("х",E19)-1)) -> 178 | S19: =IF(E19="","",--MID(E19,FIND("х",E19)+1,FIND("х",E19,FIND("х",E19)+1)-FIND("х",E19)-1)) -> 120 | T19: =IF(E19="","",--RIGHT(E19,LEN(E19)-FIND("х",E19,FIND("х",E19)+1))) -> 46 | U19: =(2*(R19+S19)+60)*(S19+T19+8)/1000000 -> 0.114144 | V19: =IF(OR(AND(R19>=2*S19,R19>=2*T19),AND(S19>=2*R19,S19>=2*T19),AND(T19>=2*R19,T19>=2*S19)),"Длинные","") | W19: =IF(OR(AND(R19<=S19/2,R19<=T19/2),AND(S19<=R19/2,S19<=T19/2),AND(T19<=R19/2,T19<=S19/2)),"Плоские","") -> Плоские | X19: =IF(LARGE($R19:$T19,1)="","",IF(LARGE($R19:$T19,1)<=99,"10-99 мм",IF(LARGE($R19:$T19,1)<=199,"100-199 мм",IF(LARGE($R19:$T19,1)<=299,"200-299 мм",IF(LARGE($R19:$T19,1)<=399,"300-399 мм",IF(LARGE($R19:$T19,1)<=499,"400-499 мм",IF(LARGE($R19:$T19,1)<=599,"500-599 мм",IF(LARGE($R19:$T19,1)<=699,"600-699 мм",IF(LARGE($R19:$T19,1)<=999,"700-999 мм","1000+ мм"))))))))) -> 100-199 мм | Y19: =IF(LARGE($R19:$T19,2)="","",IF(LARGE($R19:$T19,2)<=99,"10-99 мм",IF(LARGE($R19:$T19,2)<=199,"100-199 мм",IF(LARGE($R19:$T19,2)<=299,"200-299 мм",IF(LARGE($R19:$T19,2)<=399,"300-399 мм",IF(LARGE($R19:$T19,2)<=499,"400-499 мм",IF(LARGE($R19:$T19,2)<=599,"500-599 мм",IF(LARGE($R19:$T19,2)<=699,"600-699 мм",IF(LARGE($R19:$T19,2)<=999,"700-999 мм","1000+ мм"))))))))) -> 100-199 мм | Z19: =IF(SMALL($R19:$T19,1)="","",IF(SMALL($R19:$T19,1)<=99,"10-99 мм",IF(SMALL($R19:$T19,1)<=199,"100-199 мм",IF(SMALL($R19:$T19,1)<=299,"200-299 мм",IF(SMALL($R19:$T19,1)<=399,"300-399 мм",IF(SMALL($R19:$T19,1)<=499,"400-499 мм",IF(SMALL($R19:$T19,1)<=599,"500-599 мм",IF(SMALL($R19:$T19,1)<=699,"600-699 мм",IF(SMALL($R19:$T19,1)<=999,"700-999 мм","1000+ мм"))))))))) -> 10-99 мм | AA19: =IF(G19="","",IF(G19="Л","Лист гофрокартона",IF(G19="КД","Крышка-дно",IF(G19="С","Самосборные",IF(G19="Ч","Четырехклапанные",IF(G19="А","Архивные","Неизвестно")))))) -> Самосборные | AB19: 1.73 | AC19: =IF(O19="","",IF(O19<=1,"0-1 литров",IF(O19<=3,"2-3 литра",IF(O19<=5,"4-5 литра",IF(O19<=7,"6-7 литра",IF(O19<=9,"8-9 литров",IF(O19<=14,"10-14 литров",IF(O19<=19,"15-19 литров",IF(O19<=29,"20-29 литров",IF(O19<=49,"30-49 литров",IF(O19<=59,"50-59 литров",IF(O19<=70,"60-69 литров",IF(O19<=79,"70-79 литров",IF(O19<=89,"80-89 литров",IF(O19<=99,"90-99 литров",IF(O19<=200,"100-200 литров","200+ литров")))))))))))))))) -> 0-1 литров
